<!DOCTYPE html>
<html lang="en-US">
<!--********************************************-->
<!--*       Generated from PreTeXt source      *-->
<!--*                                          *-->
<!--*         https://pretextbook.org          *-->
<!--*                                          *-->
<!--********************************************-->
<head>
<meta http-equiv="Content-Type" content="text/html; charset=UTF-8">
<meta name="robots" content="noindex, nofollow">
</head>
<body class="ignore-math">
<h4 class="heading"><span class="type">Paragraph</span></h4>
<div class="para">The output from <a href="" class="xref" data-knowl="./knowl/listing-ex-extest3.html" title="Listing 11.3.5">ListingÂ 11.3.5</a> above demonstrates that in spite of the exception being thrown, the finally-block is executed.</div>
<span class="incontext"><a href="section-ex-catching.html#p-857" class="internal">in-context</a></span>
</body>
</html>
